<?xml version="1.0" ?>
<!-- =================================================================================== -->
<!-- |    This document was autogenerated by xacro from epsonvt6.urdf.xacro            | -->
<!-- |    EDITING THIS FILE BY HAND IS NOT RECOMMENDED                                 | -->
<!-- =================================================================================== -->
<!-- This URDF was automatically created by SolidWorks to URDF Exporter! Originally created by Stephen Brawner (brawner@gmail.com) 
     Commit Version: 1.6.0-4-g7f85cfe  Build Version: 1.6.7995.38578
     For more information, please see http://wiki.ros.org/sw_urdf_exporter -->
<robot name="epsonvt6">
  <link name="base_link">
    <inertial>
      <origin rpy="0 0 0" xyz="-0.044667 -0.0055621 -0.16755"/>
      <mass value="11.234"/>
      <inertia ixx="0.091366" ixy="0.0001185" ixz="-0.0050822" iyy="0.12176" iyz="-0.00097303" izz="0.089699"/>
    </inertial>
    <visual>
      <origin rpy="0 0 0" xyz="0 0 0"/>
      <geometry>
        <mesh filename="file:///home/gman/ros2_ws/install/robot_arm_6axis/share/robot_arm_6axis/meshes/base_link.STL"/>
        <!-- package://robot_arm_6axis/meshes/base_link.STL"-->
      </geometry>
      <material name="">
        <color rgba="0.79216 0.81961 0.93333 1"/>
      </material>
    </visual>
    <collision>
      <origin rpy="0 0 0" xyz="0 0 0"/>
      <geometry>
        <mesh filename="file:///home/gman/ros2_ws/install/robot_arm_6axis/share/robot_arm_6axis/meshes/base_link.STL"/>
      </geometry>
    </collision>
  </link>
  <link name="swivel_link">
    <inertial>
      <origin rpy="0 0 0" xyz="0.058809 0.0011943 0.10969"/>
      <mass value="5.408"/>
      <inertia ixx="0.027903" ixy="0.00011412" ixz="-0.0095523" iyy="0.035172" iyz="-0.00010229" izz="0.028875"/>
    </inertial>
    <visual>
      <origin rpy="0 0 0" xyz="0 0 0"/>
      <geometry>
        <mesh filename="file:///home/gman/ros2_ws/install/robot_arm_6axis/share/robot_arm_6axis/meshes/swivel_link.STL"/>
      </geometry>
      <material name="">
        <color rgba="0.79216 0.81961 0.93333 1"/>
      </material>
    </visual>
    <collision>
      <origin rpy="0 0 0" xyz="0 0 0"/>
      <geometry>
        <mesh filename="file:///home/gman/ros2_ws/install/robot_arm_6axis/share/robot_arm_6axis/meshes/swivel_link.STL"/>
      </geometry>
    </collision>
  </link>
  <joint name="base_swivel_joint" type="continuous">
    <origin rpy="-0.034907 0 0" xyz="0 -0.00083759 -0.023985"/>
    <parent link="base_link"/>
    <child link="swivel_link"/>
    <axis xyz="0 0 1"/>
  </joint>
  <link name="swivel_arm_link">
    <inertial>
      <origin rpy="0 0 0" xyz="-0.0185051285247269 0.0100310897931204 0.208488538519217"/>
      <mass value="1.67529418945548"/>
      <inertia ixx="0.0507941794857386" ixy="0.000730302175823613" ixz="0.000302256342382312" iyy="0.0504029422658477" iyz="2.07822625557631E-05" izz="0.00701923736777324"/>
    </inertial>
    <visual>
      <origin rpy="0 0 0" xyz="0 0 0"/>
      <geometry>
        <mesh filename="file:///home/gman/ros2_ws/install/robot_arm_6axis/share/robot_arm_6axis/meshes/swivel_arm_link.STL"/>
      </geometry>
      <material name="">
        <color rgba="0.792156862745098 0.819607843137255 0.933333333333333 1"/>
      </material>
    </visual>
    <collision>
      <origin rpy="0 0 0" xyz="0 0 0"/>
      <geometry>
        <mesh filename="file:///home/gman/ros2_ws/install/robot_arm_6axis/share/robot_arm_6axis/meshes/swivel_arm_link.STL"/>
      </geometry>
    </collision>
  </link>
  <joint name="swivel_arm_joint" type="continuous">
    <origin rpy="0 0 0" xyz="0.1 -0.09 0.149"/>
    <parent link="swivel_link"/>
    <child link="swivel_arm_link"/>
    <axis xyz="0 1 0"/>
  </joint>
  <link name="wrist_link">
    <inertial>
      <origin rpy="0 0 0" xyz="0.0214834852241277 0.0641267695907921 1.30220438060435E-06"/>
      <mass value="1.69585952099927"/>
      <inertia ixx="0.00399338568390971" ixy="-0.00062093013676303" ixz="8.00059457252006E-08" iyy="0.00511856694601518" iyz="-2.25268030979856E-07" izz="0.00569306221452427"/>
    </inertial>
    <visual>
      <origin rpy="0 0 0" xyz="0 0 0"/>
      <geometry>
        <mesh filename="file:///home/gman/ros2_ws/install/robot_arm_6axis/share/robot_arm_6axis/meshes/wrist_link.STL"/>
      </geometry>
      <material name="">
        <color rgba="0.792156862745098 0.819607843137255 0.933333333333333 1"/>
      </material>
    </visual>
    <collision>
      <origin rpy="0 0 0" xyz="0 0 0"/>
      <geometry>
        <mesh filename="file:///home/gman/ros2_ws/install/robot_arm_6axis/share/robot_arm_6axis/meshes/wrist_link.STL"/>
      </geometry>
    </collision>
  </link>
  <joint name="wrist_joint" type="continuous">
    <origin rpy="0 0 0" xyz="0 0.0216 0.42"/>
    <parent link="swivel_arm_link"/>
    <child link="wrist_link"/>
    <axis xyz="0 1 0"/>
  </joint>
  <link name="hand_link">
    <inertial>
      <origin rpy="0 0 0" xyz="0.139593875929977 -0.0246708541903937 5.31294167105401E-06"/>
      <mass value="3.66276782700147"/>
      <inertia ixx="0.0106406641258331" ixy="0.00669200808710079" ixz="2.08535425596285E-06" iyy="0.0281948606164287" iyz="-4.96579237915869E-07" izz="0.031603283969657"/>
    </inertial>
    <visual>
      <origin rpy="0 0 0" xyz="0 0 0"/>
      <geometry>
        <mesh filename="file:///home/gman/ros2_ws/install/robot_arm_6axis/share/robot_arm_6axis/meshes/hand_link.STL"/>
      </geometry>
      <material name="">
        <color rgba="0.792156862745098 0.819607843137255 0.933333333333333 1"/>
      </material>
    </visual>
    <collision>
      <origin rpy="0 0 0" xyz="0 0 0"/>
      <geometry>
        <mesh filename="file:///home/gman/ros2_ws/install/robot_arm_6axis/share/robot_arm_6axis/meshes/hand_link.STL"/>
      </geometry>
    </collision>
  </link>
  <joint name="hand_joint" type="continuous">
    <origin rpy="0 0 0" xyz="0.0905 0.06724 0"/>
    <parent link="wrist_link"/>
    <child link="hand_link"/>
    <axis xyz="1 0 0"/>
  </joint>
  <link name="finger_link">
    <inertial>
      <origin rpy="0 0 0" xyz="0.0169336580467012 0.0354511451193188 9.15129902445688E-06"/>
      <mass value="0.59831386207427"/>
      <inertia ixx="0.000779390408571983" ixy="-0.000246549727904644" ixz="-6.68846116469283E-08" iyy="0.0010025872639828" iyz="2.56605352172478E-08" izz="0.000993234046313843"/>
    </inertial>
    <visual>
      <origin rpy="0 0 0" xyz="0 0 0"/>
      <geometry>
        <mesh filename="file:///home/gman/ros2_ws/install/robot_arm_6axis/share/robot_arm_6axis/meshes/finger_link.STL"/>
      </geometry>
      <material name="">
        <color rgba="0.792156862745098 0.819607843137255 0.933333333333333 1"/>
      </material>
    </visual>
    <collision>
      <origin rpy="0 0 0" xyz="0 0 0"/>
      <geometry>
        <mesh filename="file:///home/gman/ros2_ws/install/robot_arm_6axis/share/robot_arm_6axis/meshes/finger_link.STL"/>
      </geometry>
    </collision>
  </link>
  <joint name="finger_joint" type="continuous">
    <origin rpy="0 0 0" xyz="0.3095 -0.056 0"/>
    <parent link="hand_link"/>
    <child link="finger_link"/>
    <axis xyz="0 1 0"/>
  </joint>
  <link name="tip_link">
    <inertial>
      <origin rpy="0 0 0" xyz="-0.00423168170139776 4.6619876124766E-06 1.01786927347303E-05"/>
      <mass value="0.0516677260625017"/>
      <inertia ixx="4.64734351994377E-05" ixy="2.32934900914114E-15" ixz="-3.79244342400176E-10" iyy="2.43448563893672E-05" iyz="1.49521699734775E-10" izz="2.44215854406383E-05"/>
    </inertial>
    <visual>
      <origin rpy="0 0 0" xyz="0 0 0"/>
      <geometry>
        <mesh filename="file:///home/gman/ros2_ws/install/robot_arm_6axis/share/robot_arm_6axis/meshes/tip_link.STL"/>
      </geometry>
      <material name="">
        <color rgba="0.792156862745098 0.819607843137255 0.933333333333333 1"/>
      </material>
    </visual>
    <collision>
      <origin rpy="0 0 0" xyz="0 0 0"/>
      <geometry>
        <mesh filename="file:///home/gman/ros2_ws/install/robot_arm_6axis/share/robot_arm_6axis/meshes/tip_link.STL"/>
      </geometry>
    </collision>
  </link>
  <joint name="tip_joint" type="continuous">
    <origin rpy="0 0 0" xyz="0.078 0.055495 0"/>
    <parent link="finger_link"/>
    <child link="tip_link"/>
    <axis xyz="1 0 0"/>
  </joint>
  <gazebo>
    <plugin filename="libgazebo_ros_control.so" name="gazebo_ros_control">
      <robotNamespace>/robot_arm_6axis</robotNamespace>
      <robotSimType>gazebo_ros_control/DefaultRobotHWSim</robotSimType>
    </plugin>
  </gazebo>
</robot>
